Workbook

Sheet Список навыков
A1: Название навыка | B1: Номер навыка
A2: Анализировать условия банковских вкладов | B2: 13
A3: Воспроизводить порядок действий при отзыве лицензии у банка | B3: 11
A4: Выбирать банковский вклад, ориентируясь на собственные нужды | B4: 1
A5: Выбирать между продлением и закрытием вклада по окончанию срока | B5: 8
A6: Выявлять условия досрочного закрытия вклада | B6: 7
A7: Обеспечивать безопасность вклада | B7: 12
A8: Описывать систему налогообложения по вкладам | B8: 6
A9: Определять влияние инфляции на реальную доходность вклада | B9: 5
A10: Определять выгодность пополнения вклада | B10: 3
A11: Определять доходность вклада без капитализации | B11: 16
A12: Определять доходность вклада с капитализацией | B12: 15
A13: Определять параметры вкладов | B13: 17
... A18: Частично снимать средства со вклада | B18: 4

Sheet Пререквизитные отношения
A1: Название навыка | B1: Номер навыка | C1: Пререквизит | D1: Номер навыка
A2: Выбирать банковский вклад, ориентируясь на собственные нужды | B2: =VLOOKUP(A2,'Список навыков'!A:B,2,1) -> 1 | C2: Управлять банковским вкладом | D2: =VLOOKUP(C:C,'Список навыков'!A:B,2) -> 2
A3: Управлять банковским вкладом | B3: =VLOOKUP(A3,'Список навыков'!A:B,2,1) -> 2 | C3: Определять выгодность пополнения вклада | D3: =VLOOKUP(C:C,'Список навыков'!A:B,2) -> 3
A4: Управлять банковским вкладом | B4: =VLOOKUP(A4,'Список навыков'!A:B,2,1) -> 2 | C4: Частично снимать средства со вклада | D4: =VLOOKUP(C:C,'Список навыков'!A:B,2) -> 4
A5: Управлять банковским вкладом | B5: =VLOOKUP(A5,'Список навыков'!A:B,2,1) -> 2 | C5: Определять влияние инфляции на реальную доходность вклада | D5: =VLOOKUP(C:C,'Список навыков'!A:B,2) -> 5
A6: Управлять банковским вкладом | B6: =VLOOKUP(A6,'Список навыков'!A:B,2,1) -> 2 | C6: Описывать систему налогообложения по вкладам | D6: =VLOOKUP(C:C,'Список навыков'!A:B,2) -> 6
A7: Управлять банковским вкладом | B7: =VLOOKUP(A7,'Список навыков'!A:B,2,1) -> 2 | C7: Выявлять условия досрочного закрытия вклада | D7: =VLOOKUP(C:C,'Список навыков'!A:B,2) -> 7
A8: Управлять банковским вкладом | B8: =VLOOKUP(A8,'Список навыков'!A:B,2,1) -> 2 | C8: Выбирать между продлением и закрытием вклада по окончанию срока | D8: =VLOOKUP(C:C,'Список навыков'!A:B,2) -> 8
A9: Определять выгодность пополнения вклада | B9: =VLOOKUP(A9,'Список навыков'!A:B,2,1) -> 3 | C9: Оценивать риски | D9: =VLOOKUP(C:C,'Список навыков'!A:B,2) -> 9
A10: Частично снимать средства со вклада | B10: =VLOOKUP(A10,'Список навыков'!A:B,2,1) -> 4 | C10: Оценивать риски | D10: =VLOOKUP(C:C,'Список навыков'!A:B,2) -> 9
A11: Определять влияние инфляции на реальную доходность вклада | B11: =VLOOKUP(A11,'Список навыков'!A:B,2,1) -> 5 | C11: Оценивать риски | D11: =VLOOKUP(C:C,'Список навыков'!A:B,2) -> 9
A12: Описывать систему налогообложения по вкладам | B12: =VLOOKUP(A12,'Список навыков'!A:B,2,1) -> 6 | C12: Оценивать риски | D12: =VLOOKUP(C:C,'Список навыков'!A:B,2) -> 9
A13: Выявлять условия досрочного закрытия вклада | B13: =VLOOKUP(A13,'Список навыков'!A:B,2,1) -> 7 | C13: Оценивать риски | D13: =VLOOKUP(C:C,'Список навыков'!A:B,2) -> 9
... A22: Определять доходность вклада без капитализации | B22: =VLOOKUP(A22,'Список навыков'!A:B,2,1) -> 16 | C22: Определять параметры вкладов | D22: =VLOOKUP(C:C,'Список навыков'!A:B,2) -> 17

Sheet Открытые задания
A1: Название навыка | B1: Номер навыка | C1: Условия задания | D1: Номер задания | E1: Признак Т-Тренировка Д-Диагностика | F1: Ответ1 | G1: Ответ2 | H1: ОтветN
A2: Определять выгодность пополнения вклада | B2: =VLOOKUP(A2,'Список навыков'!A:B,2,1) -> 3 | C2: Тимур открыл вклад с возможностью пополнения. С момента внесения дополнительных денежных средств проценты начисляются на общую сумму вложений. Первоначальная сумма вклада - $200\:000$ рублей, ставка - $12\%$ с ежемесячной капитализацией, срок - $4$ месяца. После начисления процентов в тот же день Тимур будет вносить по $10\:000$ рублей на вклад на протяжении $3$ месяцев. Сравните, насколько отличалась бы общая сумма накоплений, если бы он не делал ежемесячных взносов на вклад, а хранил их «под подушкой». Ответ округлите до целого числа. В ответе единицы измерения указывать не нужно. | D2: 1 | E2: Т | F2: $604$
A3: Определять выгодность пополнения вклада | B3: =VLOOKUP(A3,'Список навыков'!A:B,2,1) -> 3 | C3: Вы открыли годовой вклад на $100\:000$ рублей под $13\%$ годовых без капитализации, с пополнением. Через полгода пополнили его на $10\:000$ рублей. Какой будет сумма начисленных процентов в конце срока вклада? В ответе единицы измерения указывать не нужно. | D3: 2 | E3: Т | F3: $13650$
A4: Определять выгодность пополнения вклада | B4: =VLOOKUP(A4,'Список навыков'!A:B,2,1) -> 3 | C4: Вы открыли годовой вклад на $200\:000$ рублей под $16,2\%$ годовых без капитализации, с пополнением. Через полгода пополнили его на $50\:000$ рублей. Какой будет сумма начисленных процентов в конце срока вклада? Ответ округлите до целого числа. В ответе единицы измерения указывать не нужно. | D4: 3 | E4: Т | F4: $36450$
A5: Определять выгодность пополнения вклада | B5: =VLOOKUP(A5,'Список навыков'!A:B,2,1) -> 3 | C5: Вы открыли вклад на $7$ месяцев $300\:000$ рублей под $15\%$ годовых без капитализации, с пополнением. Через $3$ месяца пополнили его на $50\:000$ рублей. Какой будет сумма начисленных процентов в конце срока вклада? Ответ округлите до целого числа. В ответе единицы измерения указывать не нужно. | D5: 4 | E5: Т | F5: $28750$
A6: Определять выгодность пополнения вклада | B6: =VLOOKUP(A6,'Список навыков'!A:B,2,1) -> 3 | C6: Вы открыли вклад на $8$ месяцев $120\:000$ рублей под $12\%$ годовых без капитализации, с пополнением. Через $4$ месяца пополнили его на $11\:000$ рублей. Какой будет сумма начисленных процентов в конце срока вклада? Ответ округлите до целого числа. В ответе единицы измерения указывать не нужно. | D6: 5 | E6: Т | F6: $10040$
A7: Определять выгодность пополнения вклада | B7: =VLOOKUP(A7,'Список навыков'!A:B,2,1) -> 3 | C7: Эмиль открыл вклад с возможностью пополнения. С момента внесения дополнительных денежных средств проценты начисляются на общую сумму вложений. Первоначальная сумма вклада - $150\:000$ рублей, ставка - $15\%$ с ежемесячной капитализацией, срок - $4$ месяца. После начисления процентов в тот же день Эмиль будет вносить по $35\:000$ рублей на вклад на протяжении $3$ месяцев. Сравним, насколько отличалась бы общая сумма накоплений, если бы он не делал ежемесячных взносов на вклад, а хранил их «под подушкой». Ответ округлите до целого числа. В ответе единицы измерения указывать не нужно. | D7: 6 | E7: Т | F7: $2647$
A8: Определять выгодность пополнения вклада | B8: =VLOOKUP(A8,'Список навыков'!A:B,2,1) -> 3 | C8: Вы открыли годовой вклад на $160\:000$ рублей под $10,3\%$ годовых без капитализации, с пополнением. Через полгода пополнили его на $18\:000$ рублей. Какой будет сумма начисленных процентов в конце срока вклада? В ответе единицы измерения указывать не нужно. | D8: 7 | E8: Т | F8: $17407$
A9: Определять выгодность пополнения вклада | B9: =VLOOKUP(A9,'Список навыков'!A:B,2,1) -> 3 | C9: Вы открыли годовой вклад на $410\:000$ рублей под $17,9\%$ годовых без капитализации, с пополнением. Через полгода пополнили его на $57\:000$ рублей. Какой будет сумма начисленных процентов в конце срока вклада? В ответе единицы измерения указывать не нужно. | D9: 8 | E9: Т | F9: $78492$
A10: Определять выгодность пополнения вклада | B10: =VLOOKUP(A10,'Список навыков'!A:B,2,1) -> 3 | C10: Вы открыли годовой вклад на $515\:000$ рублей под $5,5\%$ годовых без капитализации, с пополнением. Через полгода пополнили его на $15\:000$ рублей. Какой будет сумма начисленных процентов в конце срока вклада? В ответе единицы измерения указывать не нужно. | D10: 9 | E10: Т | F10: $28738$
A11: Определять выгодность пополнения вклада | B11: =VLOOKUP(A11,'Список навыков'!A:B,2,1) -> 3 | C11: Вы открыли годовой вклад на $613\:000$ рублей под $5,8\%$ годовых без капитализации, с пополнением. Через полгода пополнили его на $60\:000$ рублей. Какой будет сумма начисленных процентов в конце срока вклада? В ответе единицы измерения указывать не нужно. | D11: 10 | E11: Т | F11: $37294$
A12: Определять выгодность пополнения вклада | B12: =VLOOKUP(A12,'Список навыков'!A:B,2,1) -> 3 | C12: Антон открыл вклад с возможностью пополнения. С момента внесения дополнительных денежных средств проценты начисляются на общую сумму вложений. Первоначальная сумма вклада - $180\:000$ рублей, ставка — $16\%$ с ежемесячной капитализацией, срок - $4$ месяца. После начисления процентов в тот же день Антон будет вносить по $16\:000$ рублей на вклад на протяжении $3$ месяцев. Сравним, насколько отличалась бы общая сумма накоплений, если бы он не делал ежемесячных взносов на вклад, а хранил их «под подушкой». Ответ округлите до целого числа. В ответе единицы измерения указывать не нужно. | D12: 11 | E12: Д | F12: $1291$
A13: Определять выгодность пополнения вклада | B13: =VLOOKUP(A13,'Список навыков'!A:B,2,1) -> 3 | C13: Вы открыли годовой вклад на $700\:000$ рублей под $17\%$ годовых без капитализации, с пополнением. Через полгода пополнили его на $88\:000$ рублей. Какой будет сумма начисленных процентов в конце срока вклада? В ответе единицы измерения указывать не нужно. | D13: 12 | E13: Д | F13: $126480$
... A331: Определять доходность вклада без капитализации | B331: =VLOOKUP(A331,'Список навыков'!A:B,2,1) -> 16 | C331: В банк «ООО "Шер"» поступили два вклада. Первый вклад составил $200\:000$ рублей на $3$ месяца под $3,6 \%$ годовых, второй вклад - $120\:000$ рублей на $9$ месяцев под $2 \%$ годовых. Оба вклада начисляют проценты по системе простых процентов. Проценты начисляются в момент закрытия вклада. Какие проценты (в рублях) принесет наиболее выгодный вклад? В ответ запишите только число. Если доход будет одинаковым, в ответ запишите его. | D331: 336 | E331: Д | F331: $1800$

Sheet Навыки+ Теория
A1: Название навыка | B1: Номер навыка | C1: Теория
A2: Определять выгодность пополнения вклада | B2: =VLOOKUP(A2,'Список навыков'!A:B,2,1) -> 3 | C2: # Определять выгодность пополнения вклада Пополняемость вклада - это возможность вносить на существующий вклад дополнительные средства в течение его срока, тем самым повышая будущую доходность. Вклад с пополнением выгоден в ситуациях, когда вы хотите накопить на что-то постепенно, откладывая небольшие суммы. ### Пример. Саша собирается накопить на отпуск. Для этого в феврале он открыл вклад с возможностью пополнения, с момента внесения дополнительных денежных средств проценты начисляются на общую сумму вложений. Первоначальная сумма вклада - $100000$ рублей, ставка — $15\%$ с ежемесячной капитализацией, срок - $6$ месяцев. После начисления процентов в тот же день Саша будет вносить по $20000$ рублей на вклад на протяжении $5$ месяцев. Сравним, насколько отличалась бы общая сумма накоплений Саши, если бы он не делал ежемесячных взносов на вклад с зарплаты, а хранил их «под подушкой». ### Решение. Рассчитаем пошагово доход за каждый месяц вклада с пополнениями: $$S_{1}=100000 *\left(1+0,01 * \frac{15}{12}\right)=101250 \ рублей.$$ $$S_{2}=(101250+20000) *\left(1+0,01 * \frac{15}{12}\right)=122765,625 \ рублей.$$ $$S_{3}=(122765,625+20000) *\left(7+0,01 * \frac{15}{12}\right)=144550,1953 \ рублей.$$ $$S_{4}=(144550,1953+20000) *\left(1+0,01 * \frac{15}{12}\right)=166607,0727 \ рублей.$$ $$S_{5}=(166607,0727+20000) *\left(1+0,01 * \frac{15}{12}\right)=188939,6611 \ рублей.$$ $$S_{6}=(188939,6611+20000) *\left(1+0,01 * \frac{15}{12}\right)=211551,4069 \ рублей.$$ Рассчитаем сумму вклада Саши с начисленными процентами, если бы он не делал пополнений: $$S_{6}=100000 *(1+0,01 * 15 / 12)^{6}=107738,3181 \ рубля.$$ Теперь добавим к этой сумме накопления Саши, которые хранились «под подушкой», а следовательно, не приносили доход: $$107738,3181+20000 * 5=207738,3181 \ рубля.$$ Сравним результаты с пополнением и без них: $$211551,4069 - 207738,3181 = 3813,09 \ рублей$$ дополнительного дохода принесли Саше пополнения. Ответ: $3813,09$. Ставки по пополняемым вкладам обычно ниже, чем по непополняемым, так как при снижении ставок вкладчики предпочитают пополнить вклад с более высокой ставкой, а не открывать новый, что невыгодно банкам. Условия пополнения различаются у разных банков и вкладов, поэтому при выборе вклада с пополнением важно обратить внимание на следующие параметры: 1. Сумма. Может устанавливаться минимально допустимая сумма взноса или максимальная сумма всех пополнений за период действия вклада. 2. Срок. Пополнение может быть доступно не весь период. Например, пополнить вклад можно только после $3$ месяцев с момента открытия или возможность пополнения останавливается после $6$ месяцев. 3. Периодичность. Например, допускается внесение средств раз в неделю, раз в месяц или вообще без ограничений. 4. Процентная ставка. Для новых поступлений ставка может отличаться от ставки основного вклада. Преимущество вкладов с пополнением в том, что они помогают адаптировать процесс накопления к финансовым возможностям. Можно увеличивать доходность вклада, ускоряя процесс накопления, благодаря внесению даже небольших сумм в удобное для вкладчика время. Кроме того, возможность пополнять вклад мотивирует к регулярной экономии и дисциплинирует в вопросах управления личными финансами. Какой вклад выбрать, с пополнением или без, зависит от поставленных финансовых целей. Если вы располагаете небольшой суммой, а ваша цель постепенное накопление, то лучше выбрать пополняемый вклад. Если вы хотите получить максимальный доход и можете внести крупную сумму единовременно, то лучше остановиться на вкладе без пополнения с более высокой процентной ставкой. Сегодня мы научились определять, как пополнение вкладов влияет на итоговую доходность, в каких случаях лучше выбирать пополняемый вклад и на какие условия пополнения важно обращать внимание.
A3: Описывать систему налогообложения по вкладам | B3: =VLOOKUP(A3,'Список навыков'!A:B,2,1) -> 6 | C3: # Описывать систему налогообложения по вкладам С $2021$ года процентный доход по вкладам в России облагается налогом на доходы физических лиц (НДФЛ). Однако впервые заплатить его пришлось в $2024$ году за процентные доходы, полученные по вкладам в $2023$, так как согласно указу Президента процентные доходы по вкладам за $2021$ и $2022$ годы не подлежали налогообложению. Под налогообложение попадают доходы, полученные со вкладов в рублях, валютных вкладов, а также накопительных счетов со ставкой более $1 \%$. Поскольку НДФЛ взимается в рублях, для расчёта налога к уплате процентные доходы с валютных вкладов конвертируются в рубли по курсу Банка России на дату выплаты процентов. Не имеет значения, в одном или нескольких банках были размещены вклады, для расчёта налога процентные доходы, начисленные за год, суммируются. При этом существует порог процентного дохода - часть процентного дохода, которая не подлежит налогообложению. Он рассчитывается следующим образом: **$1$ млн рублей * максимальная ключевая ставка Банка России за год на первое число каждого месяца.** В $2023$ году максимальная ставка на первое число каждого из месяцев составляла $15 \%$. Порог процентного дохода: $1$ млн рублей * $0,15=150000$ рублей. Это значит, что если совокупный доход по вкладам был ниже этой суммы, то налог в $2024$ году платить не нужно. В $2024$ году налоговая **ставка равна $13 \%$** для доходов, полученных сверх лимита в $150000$, если совокупные доходы физического лица, включая зарплату, дивиденды, проценты по вкладам и счетам, были не более $5$ млн рублей. Если такие доходы превышают $5$ млн рублей, то ставка - **$15 \%$**. ### Пример. Рассчитаем, какой налог придётся заплатить в $2024$ году, если процентный доход по вкладам, начисленный в $2023$ году, составил $170$ тыс. рублей, а совокупные доходы $2$ млн рублей. Для начала найдём налоговую базу: Полученные доходы по вкладам - пороговый доход $= 170$ тыс. рублей - $(1$ млн рублей * $0,15)=20$ тыс. рублей. Поскольку совокупные доходы не превысили $5$ млн, то ставка налога будет равна $13 \%$. $20$ тыс. рублей $* \ 0,13=2600$ рублей. В $2025$ году изменится подход к определению налоговой ставки. Теперь ставка на полученные проценты по вкладам будет равна $13 \%$, для доходов, полученных сверх порогового значения, если совокупные доходы будут в пределах $2,4$ млн рублей. При этом зарплата теперь не учитывается в сумме совокупных доходов. Для доходов сверх $2,4$ млн рублей ставка будет $15 \%$. ### Пример. Рассчитаем, какой налог придётся заплатить в $2025$ году, если процентный доход по вкладам за $2024$ год составит $1$ млн рублей, а совокупный доход, не включающий зарплату, $3$ млн рублей. Предположим, что максимальная ставка Банка России на первое число каждого месяца в $2024$ году была $21 \%$. Найдём налоговую базу: $1$ млн рублей - $(1$ млн рублей * $0,21)=790000$ рублей. Применяется повышенная ставка в $15 \%$, так как доходы превысили $2,4$ млн рублей, поэтому сумма налога составит: $790000$ * $0,15=118500$ рублей. Доходы на проценты по вкладам нужно платить самостоятельно, однако декларировать их не нужно, так как банки сами направляют информацию в Федеральную налоговую службу. Если совокупный доход превысит налоговую базу, то в Личном кабинете налогоплательщика появится уведомление с суммой налога, необходимого к уплате. Налог нужно будет заплатить до $1$ декабря года, следующего за отчётным, иначе будут начислены штрафы и пени. Не облагаются налогом процентные доходы по счетам эскроу и рублёвые вклады со ставкой не более $1 \%$ в течение всего года.
A4: Определять влияние инфляции на реальную доходность вклада | B4: =VLOOKUP(A4,'Список навыков'!A:B,2,1) -> 5 | C4: # Определять влияние инфляции на реальную доходность вклада В сентябре $2023$ года стоимость продуктов в Москве для приготовления $1$ кастрюли борща составляла примерно $284$ рубля. В сентябре $2024$ года тот же самый набор продуктов уже выходил на $325$ рублей, так как из-за инфляции произошло снижение покупательной способности денег. Одна из основных целей открытия вкладов - это защита средств от влияния инфляции. Для того чтобы оценить, как инфляция влияет на доходность вклада, на основе номинальной процентной ставки и уровня инфляции рассчитывают реальную процентную ставку. **Номинальная ставка** - это ставка, указанная в договоре по вкладу. Соответственно, номинальная доходность вклада - это процентный доход, который вы получите по вкладу. **Реальная ставка** - это номинальная ставка, скорректированная на инфляцию. С помощью неё можно рассчитать реальный процентный доход, т. е. насколько ваши деньги действительно выросли в покупательной способности после того, как были учтены изменения цен на товары и услуги. ### Формула расчёта реальной ставки: Реальная процентная ставка $=$ ((($1 \ +$ Номинальная процентная ставка) / ($1 \ +$ Инфляция)) $- \ 1$) * $100 \%$. ### Пример 1. Тимур в $2020$ году открыл вклад под $6,5 \%$ годовых, а в $2023$ году на те же сумму и срок он открыл вклад уже под более высокую ставку - $9 \%$ годовых. При этом годовая инфляция в $2020$ году была на уровне $4,91 \%$, а в $2023$ году достигла $7,42 \%$. Реальная доходность какого вклада больше? Реальная процентная ставка в $2020$ году $=(((1+6,5 \%) /(1+4,91 \%))-1) * 100 \%=1,52 \%$. Реальная процентная ставка в $2023$ году $=(((1+9 \%) /(1+7,42 \%))-1) * 100 \%=1,47 \%$. Несмотря на то, что номинальная ставка в $2023$ году по вкладу была выше, бОльшую реальную доходность принёс вклад $2020$ года. ### Пример 2. София открыла вклад на сумму $600000$ рублей на год под $16 \%$ годовых, годовая инфляция составила $8 \%$. Рассчитаем реальную доходность её вклада. Реальная процентная ставка $=(((1+16 \%) /(1+8 \%))-1) * 100 \%=7,41 \%$. Реальная доходность: $600000 * 7,41 \%=44460$ рублей. Таким образом, реальная доходность почти в $2$ раза меньше номинальной ($96000$ рублей). При высоком уровне инфляции, превышающем номинальную ставку, реальная процентная ставка может оказаться отрицательной. В такой ситуации открытие вклада всё равно нельзя назвать невыгодным вложением, так как, даже если он не принёс реального дохода, он помог снизить потери вложенных средств. Инфляция по регионам может отличаться от общероссийской. Это происходит из-за того, что регионы находятся на различных уровнях экономического развития, доходов населения, конкуренции, регулирования цен и влияния внешних факторов. В связи с этим иногда, например, когда планируются покупки в определённом регионе, полезно при оценке реальной доходности по вкладу использовать инфляцию по региону. На этом уроке мы узнали понятия реальной и номинальной доходности, научились рассчитывать реальную доходность с учётом инфляции и сравнивать ставки по вкладу с уровнем инфляции. Предлагаем решить несколько задач самостоятельно и проверить себя. Желаем удачи! ### Задачи для самостоятельной проверки **Задача 1.** Николай решил внести на срочный годовой вклад $1300000$ рублей под $17 \%$ процентов годовых. Инфляция за год составила $13 \%$. Найдите разницу между номинальной и реальной доходностью вклада. При расчёте ставки ответ округляйте до двух знаков после запятой. <details> <summary>Решение</summary> Номинальная доходность вклада $=1300000 * 17 \ % = 221000$. Реальная процентная ставка $=(((1+17 \%) /(1+13 \%))-1) * 100 \% = 3,54 \%$. Реальная доходность $=1300000 * 3,54 \%=46020$. Разница $=221000-46020=174980$ рублей. **Ответ:** реальная доходность оказалась на $174980$ рублей ниже номинальной. </details> **Задача 2.** Сравните, реальная доходность какого вклада и насколько выше при прочих равных, если номинальная ставка первого вклада $7,6 \%$ годовых при $5\%$ годовом уровне инфляции, а второго - $8\%$ при $6,4 \%$ инфляции. При расчёте ставки ответ округляйте до двух знаков после запятой. <details> <summary>Решение</summary> Реальная процентная ставка вклада $1=(((1+7,6 \%) /(1+5 \%))-1) * 100 \%=2,48 \%$. Реальная процентная ставка вклада $2=(((1+8 \%) /(1+6,4 \%))-1) * 100 \%=1,5 \%$. Разница $=2,48 \%-1,5 \%=0,97$. **Ответ:** на $0,97$ п.п. реальная процентная ставка первого вклада выше, чем второго. </details>
A5: Выбирать между продлением и закрытием вклада по окончанию срока | B5: =VLOOKUP(A5,'Список навыков'!A:B,2,1) -> 8 | C5: # Выбирать между продлением и закрытием вклада по окончании срока При завершении срока вклада встаёт важный финансовый вопрос: продлить вклад или закрыть его? Чтобы принять правильное решение, необходимо разобраться в условиях продления, провести анализ текущих рыночных предложений и оценить свои личные финансовые цели. Пролонгация вклада - это автоматическое продление вклада на новый срок. В договоре указывается, на каких условиях будет происходить продление: на прежних или с изменением ставки или срока вклада. Банку пролонгация выгодна тем, что помогает избегать оттока средств вкладчиков, а также снижает издержки на рекламные кампании для привлечения клиентов, перезаключение договоров. Вкладчикам пролонгация помогает обеспечивать постоянный рост средств без необходимости участвовать в процессе. Это особенно удобно, когда целью стоит создание крупных накоплений, например, на покупку автомобиля, жилья, образование детей. Автоматическое продление выгодно, если процентная ставка на уровне рыночных или выше. Если же рыночные процентные ставки растут, а ставка по вашему вкладу остаётся прежней или снижается, отказ от пролонгации и поиск нового вклада с более выгодными условиями может принести больший доход. Также от продления вклада лучше отказаться, если вы планируете использовать сумму вклада для каких-то покупок в ближайшем будущем или других финансовых инструментов. ### Пример. Георгий открыл вклад на сумму $250000$ под $7\%$ годовых. Проценты в конце срока начисляются на вклад. По условиям договора вклад автоматически пролонгируется на следующий год с сохранением той же процентной ставки. Георгий решил не закрывать вклад и позволил ему автоматически продлиться ещё на два года. Необходимо рассчитать итоговую сумму вклада после трёх лет. Пролонгация происходит после начисления процентов. Поскольку проценты начисляются и остаются на вкладе, воспользуемся формулой сложных процентов: $$S_{3}=250000 *(1+0,01 * 7)^{3}=306260,75 \ рублей.$$ Сегодня мы узнали, что, выбирая между продлением и закрытием вклада, важно сравнить текущие предложения по процентным ставкам на новые вклады с предлагаемым, а также проверить соответствие личным финансовым целям.
A6: Частично снимать средства со вклада | B6: =VLOOKUP(A6,'Список навыков'!A:B,2,1) -> 4 | C6: # Частично снимать средства со вклада Существуют вклады с возможностью частичного снятия средств, т. е. вкладчик может снимать деньги с вклада, не закрывая его. Конечно, в этом случае произойдёт потеря доходности, поскольку проценты начисляются на оставшуюся сумму вклада, однако досрочное закрытие приводит к бОльшим потерям. Такие вклады удобны, если вы хотите получать доход с временно неиспользуемых денежных средств и при этом в случае непредвиденных трат иметь возможность воспользоваться частью из них, сохраняя какой-то доход. Вклады с частичным снятием обладают своими особенностями. Часто банки устанавливают для них размер минимального неснижаемого остатка, т. е. минимальную сумму, которая должна оставаться на вкладе после любого частичного снятия средств. Например, во вкладе предусмотрен минимальный неснижаемый остаток - $30000$ рублей. Это значит, что после снятия средств на вкладе должно оставаться не менее $30000$ рублей. Если вкладчик решит снять средства больше этого лимита, то операция будет отклонена, либо банк предложит досрочное закрытие вклада, что приведёт к потере процентов. Кроме того, может быть установлено ограничение по количеству операций снятия. Например, вывод средств - не более $1$ раза в месяц. Ставки по таким вкладам обычно ниже, чем по вкладам с пополнением, поскольку они наименее выгодны для банка. ### Пример. Варвара открыла годовой вклад на $500000$ рублей под $14 \%$ годовых без капитализации, с частичным снятием. Через полгода она заболела и сняла $60$ тысяч на лечение. Узнаем разницу в доходности между вкладом с частичным снятием средств и вкладом без снятия. Рассчитаем процентный доход вклада через год без снятия: $$500000 *(0,01 * 14)=70000 \ рублей.$$ Рассчитаем процентный доход вклада с частичным снятием. Первое полугодие: $$500000 *(0,01 * 14 / 2)=35000 \ рублей.$$ Второе полугодие: $$(500000-60000) *(0,01 * 74 / 2)=30800 \ рублей.$$ Общий процентный доход за год: $$35000+30800=65800 \ рублей.$$ Разница между доходностью вкладов: $$70000-65800=4200 \ рублей.$$ Ответ: частичное снятие средств привело к потере потенциальной доходности в размере $4200$ рублей. Сегодня мы узнали о преимуществах и недостатках вкладов с частичным снятием средств и на какие условия стоит обращать внимание, выбирая такой вклад.
A7: Сравнивать вклады с учётом страхования вкладов | B7: =VLOOKUP(A7,'Список навыков'!A:B,2,1) -> 10 | C7: # Сравнивать вклады с учётом страхования вкладов Все российские банки, привлекающие денежные средства физических лиц, обязаны участвовать в системе страхования вкладов (ССВ) - государственной программе, защищающей банковские сбережения граждан. Если у банка отзывают лицензию или вводят мораторий на удовлетворение требований кредиторов, то в рамках этой программы агентство по страхованию вкладов (АСВ) гарантирует возврат вложенных средств. Сегодня на занятии мы разберём, как максимально обезопасить свои вложения, зная особенности ССВ. Страховому возмещению подлежат $100 \%$ средств, размещённых на счетах и вкладах, включая начисленные проценты, но его максимальный размер на одного вкладчика в одном банке составляет $1,4$ млн рублей. Представим, что ты планируешь сделать банковский вклад на $2$ млн рублей и хочешь минимизировать риск потери средств. В этом случае лучше открыть по вкладу в двух разных банках, каждый из которых не будет превышать $1,4$ млн рублей. Так, даже если одновременно в двух банках отзовут лицензии, то ты сможешь вернуть все вложенные средства + начисленные проценты, а не только $1,4$ млн рублей, как если бы они лежали в одном банке. При наличии особых обстоятельств можно получить повышенное возмещение до $10$ млн рублей. К таким обстоятельствам относятся: - продажа жилья; - получение наследства; - возмещение ущерба, причинённого жизни, здоровью или личному имуществу, получение социальных выплат, пособий, компенсационных и иных выплат; - исполнение решения суда; - получение грантов в форме субсидий. Важно, чтобы средства от перечисленных обстоятельств были получены в течение трёх месяцев до наступления страхового случая. Если после отзыва лицензии вкладчику положено повышенное возмещение, но у него в том же банке есть ещё вклад, попадающий под стандартное возмещение $1,4$ млн рублей, то возмещения будут суммироваться и не должны будут превысить $10$ млн рублей. Помимо этого, возмещение до $10$ млн рублей можно получить по счетам эскроу, открытым для сделок купли-продажи недвижимости или долевого строительства. Счёт эскроу - это счёт для безопасного проведения расчётов между покупателем и продавцом. Покупатель кладёт деньги для оплаты сделки в банк на такой счёт, а продавец может их забрать только после выполнения определённых условий, которые прописаны в договоре. Страховое возмещение по счёту эскроу, открытому для расчётов по сделкам купли-продажи недвижимости, рассчитывается и выплачивается отдельно от страхового возмещения по иным вкладам, в отличие от повышенного возмещения при особых обстоятельствах, в том числе отдельно от страхового возмещения по счёту эскроу, открытому для расчётов по договору участия в долевом строительстве. Также существуют категории сбережений, которые вообще не подлежат возмещению через ССВ: средства на банковских счетах адвокатов и нотариусов для ведения профессиональной деятельности, электронные деньги, металлические счета, вклады в зарубежных филиалах российских банков, средства, переданные в доверительное управление. Требования по вкладам, превышающие выплаченное страховое возмещение или непопадающие под него, погашаются в ходе ликвидационных процедур в отношении банка. ### Пример 1. Егор открыл вклад на сумму $850$ тыс. рублей. Через несколько месяцев банк, где был открыт вклад, лишился лицензии. Егор обратился в Агентство по страхованию вкладов и получил всю сумму своего вклада обратно, поскольку она не превышала $1,4$ миллиона рублей. ### Пример 2. Алиса продала квартиру и получила на свой счёт $6$ миллионов рублей. Если произойдёт банкротство её банка в течение трёх месяцев со дня поступления средств на счёт и перехода права собственности, то средства будут относиться к категории выплат, подлежащих повышенному возмещению и Анна сможет получить обратно все $6$ млн рублей. Если же банкротство произойдёт позже, то Анна получит только $1,4$ млн рублей, так как средства уже будут подходить только под категорию стандартного возмещения. ### Пример 3. Андрей открыл металлический счёт в банке. В случае отзыва лицензии у банка Андрей не сможет претендовать на страховое возмещение, так как металлические счета не попадают под страхование АСВ. На этом уроке мы научились, как распределять свои сбережения между банками для максимальной защиты средств при потенциальном отзыве лицензии у банка. Предлагаем решить несколько задач самостоятельно и проверить себя. Желаем удачи! ### Задачи для самостоятельной проверки **Задача 1.** Иван имеет два вклада в разных банках: в первом банке вклад на $1$ миллион рублей, во втором - на $300$ тысяч рублей. Оба банка потеряли лицензию. Какую сумму Иван получит в качестве возмещения? <details> <summary>Решение</summary> Сумма первого вклада - $1$ млн рублей, второго - $300$ тыс. рублей. Общая сумма меньше $1,4$ миллиона рублей, следовательно, Иван получит полное возмещение: $1$ млн $+ \ 300$ тыс. $=1300000$ руб. **Ответ: $1300000$ рублей.** </details> **Задача 2.** Ольга открыла счёт эскроу для покупки квартиры. На счету находилось $9$ миллионов рублей. Банк, в котором был открыт счёт, лишился лицензии. Какая сумма будет возмещена Ольге? <details> <summary>Решение</summary> Средства на счетах эскроу страхуются на общую сумму до $10$ млн рублей. Поэтому Ольга получит полное возмещение в размере $9$ млн рублей. **Ответ: $9000000$ рублей.** </details> **Задача 3.** Алексей открыл вклад в банке на сумму $1,5$ млн рублей. Спустя некоторое время банк обанкротился. Какая сумма будет выплачена Алексею в рамках системы страхования вкладов? <details> <summary>Решение</summary> Максимальная сумма страхового возмещения составляет $1,4$ млн рублей. Алексей получит $1,4$ миллиона, а оставшаяся сумма ($100$ тысяч рублей) может быть возвращена только после завершения процедуры банкротства банка. **Ответ: $1400000$ рублей.** </details>
A8: Выявлять условия досрочного закрытия вклада | B8: =VLOOKUP(A8,'Список навыков'!A:B,2,1) -> 7 | C8: # Выявлять условия досрочного закрытия вклада Деньги на вкладе являются достаточно ликвидными, потому что можно досрочно закрыть вклад и вернуть вложенные средства, если они понадобятся. Благодаря этому банковский вклад - один из самых удобных инструментов для формирования финансовой подушки безопасности. Однако если вы досрочно закроете вклад, то потеряете доходность, так как проценты за фактический срок вклада, скорее всего, будут начислены по более низкой ставке вклада или не начислятся вовсе. Обычно ставка при досрочном изъятии средств становится минимальной, близкой к ставкам вкладов до востребования, но иногда для привлечения клиентов банки предлагают льготное досрочное расторжение. При льготном расторжении ставки ниже, чем по основному вкладу, но значительно выше ставок вкладов до востребования. Перед открытием вклада стоит внимательно изучить, какие предложения по досрочному закрытию вкладов предлагают разные банки для минимизации рисков потери средств в будущем, при возникновении необходимости досрочного закрытия вклада. ### Пример. Юрий открыл вклад на $130000$ рублей под $12 \%$ годовых с ежемесячной капитализацией на $6$ месяцев. Через $3$ месяца Юрий досрочно закрыл вклад. По условию договора при досрочном расторжении ставка меняется на $0,01 \%.$ Рассчитаем, какой была бы сумма вклада через $3$ месяца, если бы мужчина не стал досрочно закрывать вклад, и насколько она отличается от той, что Юрий получил. Сумма вклада на конец третьего месяца, если бы Юрий не изъял средства: $$S_{3}=130000 *(1+0,12 / 12)^{3}=133939,13 \ рублей.$$ При досрочном закрытии вклада банк делает перерасчёт, поэтому сумма, полученная Юрием, составит: $$S_{3}=130000 *(1+0,01 * 0,01 / 12)^{3}=130003,25 \ рубля.$$ Потери Юрия из-за досрочного погашения: $$133939,13 - 130003,25=3935,88 \ рублей.$$ Ответ: $3935,88$ рублей процентного дохода потерял Юрий из-за досрочного погашения вклада. Для того чтобы снизить потери, существуют альтернативы досрочному закрытию. Например, можно открыть вклад с условием снятия, который даст возможность снимать часть средств, тем самым снижая сумму, на которую будут начисляться проценты, но не снижая ставку. Также альтернативой может служить кредит под залог вклада, т. е. при просрочке платежа по кредиту банк взыщет средства со вклада. Сумма кредита в таком случае ограничивается размером вклада. Ставка будет выше, чем ставка по вкладу, но ниже, чем по обычным кредитам, благодаря обеспеченности вкладом. Кредит под залог вклада может быть выгоден в том случае, когда деньги нужны на короткий срок и их сумма значительно меньше суммы вклада, а полученные проценты по вкладу перекроют начисленные проценты по кредиту. Если привлечение средств из других источников для покрытия непредвиденных расходов превышает размер процентов, которые могут быть получены от вклада, то лучше прибегнуть к досрочному закрытию. Сегодня мы разобрали типичные условия досрочного закрытия вкладов, расчёт потерь и альтернатив досрочному закрытию.
A9: Анализировать условия банковских вкладов | B9: =VLOOKUP(A9,'Список навыков'!A:B,2,1) -> 13 | C9: # Анализировать условия банковских вкладов Чтобы иметь финансовую подушку безопасности и обеспечить себя средствами на будущее, необходимо делать сбережения. Вклады — удобный и выгодный инструмент для сбережений, поскольку они предлагают стабильный доход в виде процентов, защищены системой страхования вкладов и позволяют сохранить средства с минимальными рисками. При выборе вклада важно учитывать **следующие ключевые факторы**, которые определяют выгоду и риски для вкладчика: 1. **Тип вклада.** В зависимости от выбранного типа вклада (срочного, вклада до востребования, накопительного) он позволяет частично или полностью снимать деньги в течение срока действия, а также определяет ограничения на снятие средств или понижение ставки процента в случаях, когда происходит досрочное снятие средств. 2. **Срок вклада.** Срок размещения средств влияет на то, когда вкладчик сможет вернуть свои деньги с процентами. Краткосрочные вклады обычно предполагают более низкую процентную ставку, в то время как долгосрочные вложения могут быть более выгодными, но они предполагают невозможность доступа к средствам до конца срока. Важно учитывать собственные нужды: если деньги могут понадобиться раньше времени, краткосрочные вклады будут лучшим вариантом. 3. **Процентная ставка.** Процентная ставка - это основной фактор, влияющий на доходность вклада. **Чем выше ставка, тем больше доход вкладчик получит за определённый срок.** Ставки могут быть фиксированными, а могут изменяться в зависимости от рыночной ситуации. Для фиксированных вкладов процентная ставка устанавливается на весь срок действия вклада, что гарантирует постоянный доход. Для вкладов с плавающей ставкой доход может изменяться, что делает такие вложения более рискованными, но с потенциалом для повышения доходности. Дифференцированные ставки предлагают большую доходность за больший срок действия вклада или большую сумму на счёте. 4. **Схема начисления процентов.** Этот фактор напрямую влияет на доходность по вкладу и то, каким образом выгодно устроить снятие средств с вклада, если оно необходимо. Так, например, если проценты начисляются на остаток средств на счёте раз в год в день пополнения вклада, это означает, что начисление процентов учитывает только ту сумму, которая имеется на вашем счёте в конкретный момент времени. В этом случае снятие средств со счёта в этот день нежелательно, так как это снизит доходность. Манипуляции со средствами в другие дни не приведут к такому результату, если сумма по вкладу в результате снятий и пополнения средств не изменится. 5. **Условия капитализации процентов.** Капитализация процентов - это процесс добавления начисленных процентов к сумме вклада. В зависимости от частоты капитализации (ежемесячная, ежеквартальная, ежегодная) **доходность** может **значительно различаться**. Чем чаще происходит капитализация, тем больший доход может получить вкладчик. **Эффективная процентная ставка** позволяет сравнить реальные доходы по вкладам, **учитывая частоту капитализации процентов**. Используя эффективную процентную ставку, можно выбрать наиболее выгодные вклады, так как она агрегирует информацию о номинальной ставке процента и условиях капитализации каждого из вкладов. 6. **Надёжность банка.** Вкладчики должны обращать внимание на рейтинг банка, его финансовое положение и участие в **системе страхования вкладов**, которая гарантирует возврат средств в случае банкротства финансового учреждения в пределах установленного лимита. Надёжность банка важнее других факторов, потому что даже высокая процентная ставка или выгодные условия не обеспечат безопасности ваших средств, если банк окажется ненадёжным. Помимо перечисленных выше основных характеристик банковских вкладов инвестор должен учитывать и конкретные условия **законодательства** и **договора с банком**, складывающиеся в конкретный момент времени. Так, например, хранение денег на депозитах в России по законодательству предусматривает **удержание налога на проценты**, если они превышают минимальный необлагаемый доход. При расчёте реальной доходности вклада важно обновлять информацию о том, **какая ставка налога действует именно сейчас**. Кроме того, стоит получить актуальную информацию **о лимите страхового возмещения**. По состоянию на декабрь $2024$ года эта сумма составляет **$1,4$ миллиона рублей на одного вкладчика в одном банке**, однако она может измениться вследствие экономических колебаний. Детали договора с банком, в котором планируется открытие депозита, также важны. В некоторых случаях вкладчик может пожелать вернуть деньги до окончания срока действия вклада. Важно учитывать, какие штрафные санкции или пониженные процентные ставки могут применяться при досрочном снятии средств. Также некоторые банки предлагают дополнительные бонусы или услуги для вкладчиков, например акции, повышающие доходность вклада. При сравнении вкладов стоит учитывать такие бонусы, так как они могут повысить общую привлекательность предложения.
A10: Определять параметры вкладов | B10: =VLOOKUP(A10,'Список навыков'!A:B,2,1) -> 17 | C10: # Определять параметры вкладов Чтобы иметь финансовую подушку безопасности и обеспечить себя средствами на будущее, необходимо делать сбережения. Вклады — удобный и выгодный инструмент для сбережений, поскольку они предлагают стабильный доход в виде процентов, защищены системой страхования вкладов и позволяют сохранить средства с минимальными рисками. При выборе подходящего вклада следует уметь определять его параметры - например, тип вклада, срок размещения на нём денежных средств и устройство процентной ставки. Все эти параметры влияют на будущий доход от размещения денег на счёте, доступность средств во время нахождения на депозите, потенциальные риски и т. д. ### Типы вкладов 1. **Срочные вклады** - вклады, которые открываются **на определённый срок**, например на $3$ месяца. При выборе такого вклада забрать деньги с депозита без потери выгоды будет невозможно: если вывести деньги с депозита до окончания срока, проценты могут быть снижены или вообще не начислены. Таким образом, срочные вклады дают банку наибольшую определённость по возможным срокам использования денег. Это ведёт к тому, что проценты по срочным вкладам обычно выше. 2. **Вклады до востребования** - это вклады, снимать средства с которых можно в любое время. Также такие вклады после их открытия можно и пополнять. Важное отличие вклада до востребования в том, что осуществлять манипуляции со средствами в этом случае можно **без потери процентов**. Как нетрудно догадаться, свободный доступ к распоряжению средствами на вкладе снижает начисляемые по вкладу проценты, так как банк не может точно планировать, сколько времени деньги будут находиться на счёте. 3. **Накопительные вклады** - это гибридный вариант вкладов, сочетающий в себе черты срочного вклада и вклада до востребования. Такие вклады, во-первых, позволяют пополнять вклад или снимать деньги в определённой форме (например, не в любой момент, а только ежемесячно). В зависимости от условий банка может быть предусмотрено определённое ограничение на количество снятий или пополнений. Также накопительные вклады предусматривают определённую форму начисления процентов (например, они могут начисляться на минимальный или средний остаток средств в течение определённого периода). Ставка по таким вкладам, соответственно, может быть выше, чем у вклада до востребования, но ниже, чем у срочного вклада. Подчеркнём, что для вкладов, предусматривающих изменение суммы на счёте, существуют **разные схемы начисления процентов**. Например, проценты могут начисляться: - На остаток средств на счёте - проценты начисляются на ту сумму, которая имеется на вашем счёте в конкретный момент времени (ежедневно, ежемесячно, ежегодно). - На минимальный остаток - проценты начисляются на минимальную сумму, которая была на счёте за установленный период. - На усреднённый баланс - проценты начисляются на среднюю сумму, которая была на вашем счёте в течение определённого периода. Вклады также различаются по срокам размещения денег. Решение о длительности вложения денег приводит к вариации в величине процентной ставки, доступности средств и возможных рисках. **Краткосрочные вклады** открываются на небольшой срок длительностью до $1$ года, **среднесрочные** - на срок от $1$ года до $2$-$3$ лет, **долгосрочные** - от $3$ до $5$ лет и более. Краткосрочные вклады, как правило, менее подвержены рискам, чем долгосрочные, так как они открываются на небольшой срок. Также они характеризуются высокой ликвидностью, но более низкими по сравнению с долгосрочными вкладами процентными ставками, поскольку обеспечивают банкам меньший срок пользования средствами. **Среднесрочные вклады** подвержены рискам экономических изменений, но более стабильны, чем краткосрочные. Ставки по **долгосрочным вкладам** наиболее высокие, так как банк получает возможность использовать деньги во время длительного периода. Проценты по среднесрочным и долгосрочным вкладам часто капитализируются (добавляются к основному балансу), что позволяет получать дополнительный доход — ещё и от начисленных процентов. В зависимости от того, как устанавливаются процентные ставки по вкладам, их можно разделить на **фиксированные**, **плавающие** и **дифференцированные**. **Фиксированные ставки** остаются неизменными на весь срок действия вклада вне зависимости от изменения ставок на рынке, инфляции или экономической ситуации в целом. **Плавающая ставка** по вкладу - это ставка, которая пересматривается через определённые установленные промежутки времени. На изменение ставки влияют текущие рыночные условия. Вклады с плавающими ставками связаны с большей неопределённостью, чем вклады с фиксированными ставками: в этом случае сложнее предсказать, какой доход будет в итоге получен. Ставка по вкладу называется **дифференцированной**, если она меняется в зависимости от периода времени, в течение которого поддерживается вклад, или от суммы на вкладе. Так, например, для депозитов с большей суммой (например, от $1$ миллиона рублей) ставки могут достигать больших значений. Еще дифференцированная ставка по вкладу может предполагать разные величины процентных ставок в разные периоды депозита: например, ставка на первые полгода может быть ниже, чем при пролонгировании вклада на дальнейшие месяцы.
A11: Сравнивать процентные ставки по вкладам | B11: =VLOOKUP(A11,'Список навыков'!A:B,2,1) -> 14 | C11: # Сравнивать процентные ставки по вкладам Как мы уже выяснили, разные вклады могут иметь разные правила: например, проценты по ним могут начисляться и капитализироваться с разной периодичностью. Вследствие большого разнообразия условий банковских вкладов возникает сложность в сопоставлении и сравнении их доходностей. Для сопоставления вкладов с разными условиями пользуются эффективной процентной ставкой. **Эффективная процентная ставка** - это ставка, которая отражает **реальную доходность вклада** с учётом всех условий, включая частоту капитализации процентов. Такая процентная ставка показывает, сколько процентов фактически будет начислено на счёт клиента банка за установленный период инвестирования (например, за год) с учётом особенностей капитализации процентов (ежемесячной, ежеквартальной и т. д.) в конкретном случае. Другими словами, эффективная процентная ставка отражает, какую общую выгоду от вклада получит клиент к концу периода инвестирования. Эффективная процентная ставка - особенно удобный инструмент сопоставления доходностей вкладов в случае, если проценты на сумму вклада начисляются чаще, чем один раз в год: например, ежемесячно или ежеквартально. Дело в том, что в таком случае **реальная доходность по вкладу будет выше номинальной ставки**, то есть той фиксированной ставки процента по вкладу за оговоренный период, что указана в условиях вклада. В случае ежемесячной или ежеквартальной капитализации процентов начисляемые проценты, соответственно, каждый месяц или квартал присоединяются к телу вклада. Это означает, что, например, за год нахождения денег на вкладе сумма депозита будет расти, ведь дальнейшее начисление процентов не только на первоначальную сумму вклада, но и на уже начисленные проценты будет увеличивать реальную доходность. ### Пример. Предположим, что Агнию Захаровну интересует сопоставление двух разных вкладов: она готова выбрать вклад с наибольшей доходностью и внести деньги на депозит сроком на $1$ год. В таком случае нам необходимо посчитать, какую величину для каждого из вкладов составляет годовая эффективная процентная ставка. Для расчёта $E$, то есть эффективной процентной ставки (в годовых процентах), Агнии Захаровне потребуются данные о номинальных годовых процентных ставках $\left(i_{1}, i_{2}\right)$ каждого из вкладов, которые необходимо сравнить, а также о количестве периодов капитализации процентов в каждом году для каждого из вкладов $\left(n_{1}, n_{2}\right)$. При наличии этих данных о вкладах достаточно будет воспользоваться формулой: $$ E=\left(1+\frac{i}{n}\right)^{n}-1 $$ Пусть вклад №1 обладает номинальной ставкой по вкладу $i_{1}=12 \%$ годовых с ежемесячной капитализацией. Ежемесячная капитализация процентов означает, что проценты начисляются $12$ раз в год, поэтому $n_{1}=12$. Вклад №2 обещает ежеквартальную капитализацию процентов ( $n_{2}=4$ ), однако номинальная процентная ставка составляет $20 \%$ годовых. Какой вклад стоит выбрать Агнии Захаровне? Рассчитаем эффективную процентную ставку для первого вклада: $E_{1}=\left(1+\frac{i}{n}\right)^{n}-1=\left(1+\frac{0,12}{12}\right)^{12}-1=(1+0,01)^{12}-1 \approx 0,1268$ или $12,68\%$. Получаем, что годовая эффективная процентная ставка по вкладу №1 составляет $12,68\%$ годовых. Рассчитаем эффективную процентную ставку для второго вклада: $E_{2}=\left(1+\frac{i}{n}\right)^{n}-1=\left(1+\frac{0,2}{4}\right)^{4}-1 \approx 0,2155$ или $21,55 \%$. Заметьте, что номинальные ставки по вкладам 1 и 2 составляют $12 \%$ и $20 \%$ годовых, в то время как реальная доходность составляет $12,68 \%$ и $21,55 \%$. Агния Захаровна, конечно, предпочтёт вклад №2. Таким образом, эффективная процентная ставка позволяет эффективно сравнивать разные предложения с различной периодичностью капитализации.
A12: Выбирать банковский вклад, ориентируясь на собственные нужды | B12: =VLOOKUP(A12,'Список навыков'!A:B,2,1) -> 1 | C12: # Выбирать банковский вклад, ориентируясь на собственные нужды Независимо от уровня дохода, умение откладывать часть заработанных денег является важной частью финансового планирования и позволяет избежать финансовых трудностей. Один из самых популярных сберегательный инструментов - банковский вклад. Это связано с тем, что он обладает высокой надёжностью и ликвидностью, приносит процентный доход. Существует ли идеальный банковский вклад? Нет: как и любой финансовый инструмент, банковский вклад нужно подбирать исходя из своих финансовых целей. Например, если вы планируете долгосрочные накопления, то стоит обратить внимание на вклады с высокой процентной ставкой и длительным сроком хранения. Если ваша цель накопление на непредвиденные расходы, то подойдут вклады с возможностью частого пополнения и снятия средств. Для того чтобы выбрать наиболее выгодный вклад, важно помнить об изученных в данном модуле параметрах вкладов, а также о том, как они влияют на доходность. Если ты не помнишь, как какой-то из параметров ниже влияет на вклад, то ты всегда можешь вернуться к навыку, который изучался ранее, и освежить в памяти детали. Важные параметры вкладов: 1. Виды вкладов: срочный, до востребования, накопительный. 2. Сроки вкладов: краткосрочные, среднесрочные, долгосрочные. 3. Типы процентных ставок: фиксированная, плавающая, дифференцированная. 4. Капитализация процентов. 5. Эффективная процентная ставка. 6. Страхование вкладов. 7. Признаки проблем у банка. 8. Условия пополнения вкладов. 9. Влияние пополнений на итоговую доходность. 10. Возможность пополнения и снятия средств с вклада. 11. Условия пролонгации. 12. Условия досрочного закрытия вклада.
A13: Оценивать риски | B13: =VLOOKUP(A13,'Список навыков'!A:B,2,1) -> 9 | C13: # Оценивать риски Что необходимо помнить при оценке рисков банковского вклада: **Надёжность банка** - Наличие действующей лицензии ЦБ РФ. - Участие в системе страхования вкладов (ССВ). - Финансовые показатели банка (отчёты, рейтинги). **Страховая защита вклада** - Стандартный лимит возмещения - $1,4$ млн руб. на одного вкладчика в одном банке. - Повышенное возмещение - до $10$ млн руб. в особых случаях. - Отдельное страхование счетов эскроу - до $10$ млн руб. **Безопасность размещения средств** - Разделение крупных сумм между разными банками. - Использование только официальных каналов для открытия вклада. - Внимательное изучение договора. **Действия при проблемах банка** - Мониторинг признаков проблем (задержки выплат, снижение капитала и др.), проверка статуса банка на сайтах ЦБ РФ и АСВ, поиск информации о финансовой отчётности банка. - Порядок получения возмещения через АСВ: подача заявления на получение компенсации в банк-агент или на сайт ACB, ожидание проверки данных и одобрения заявки. - Возможность участия в процессе ликвидации банка помогает спасти средства, если сумма на депозите превышала лимит страхового возмещения.
... A18: Определять доходность вклада без капитализации | B18: =VLOOKUP(A18,'Список навыков'!A:B,2,1) -> 16 | C18: # Определять доходность вклада без капитализации Сначала научимся определять доходность вклада **без капитализации процентов.** В таком случае проценты начисляются только на **изначально положенную на депозит сумму,** а начисления процентов на начисленные в процессе нахождения денег на депозите проценты **не происходит.** Для расчёта доходности вклада без капитализации процентов следует пользоваться формулой для расчёта **простых процентов.** Пусть $S_{0}$ - сумма вклада, на которую будут начисляться проценты, $i$ - фиксированная ставка процента по вкладу за оговоренный период, например год, $n$ - число периодов нахождения денег на депозите, за которое будут начисляться проценты. В таком случае формула для расчёта простых процентов позволяет узнать, какая сумма окажется на вкладе через $n$ периодов: $$ S_{n}=S_{0} *(1+0,01 * i * n) $$ Доходность по вкладу (сумма процентов, начисленных за $n$ периодов нахождения денег на депозите) вычисляется по формуле: $$ I_{n}=S_{0} *(0,01 * i * n) $$ Простые проценты обычно используются, когда процентная ставка по вкладу остаётся неизменной в течение всего времени, а начисление происходит по окончании каждого периода (например, каждый год, каждый месяц или каждый квартал). ### Пример 1. Мавра Николавна открывает вклад в банке: депозит в $10000$ рублей под $5 \%$ годовых. Она уверена, что деньги не потребуются ей в течение двух лет, поэтому депозит открывается на два года. Сколько денег окажется на вкладе Мавры Николавны по истечении двух лет и какова будет доходность такого вклада? По условию задачи, $S_{0}=10000, i =5, n =2$. По формуле расчёта простых процентов получаем, что сумма на вкладе Мавры Николавны через $2$ года составит: $S_{2}=S_{0} * (1+0,01 * i * n)=10000 *(1+0,05 * 2)=11000$ рублей. Заметим, что каждый год Мавра Николавна будет получать по $5 \%$ от положенной ею на вклад суммы $S_{0}=10000$ рублей. В первый год существования вклада $5 \%$ от $10000$ рублей составляет $10000 * 0,05=500$ рублей. Так как **капитализации процентов не происходит,** полученные в первый год $500$ рублей дохода по вкладу не добавятся к **«телу депозита»** - внесённым изначально десяти тысячам. В таком случае доходность вклада за второй год его существования не будет отличаться от первого: всё те же $10000$ рублей принесут $5 \%$ годовых - $500$ рублей. Сумма процентов, начисленных за $2$ года нахождения денег на депозите, составит $500+500=1000$ рублей. Тот же результат можно было получить с помощью обобщёной формулы $I_{2} = 10000 *(0,01 * 5 * 2)=1000$ рублей. Обратите внимание, что сумма, которая окажется на вкладе Мавры Николавны через $2$ года, в точности равна сумме, которая была положена на вклад ($10000$ рублей) и добавленной к ней теперь процентам за два года (по $500$ рублей за каждый год). Таким образом, при начислении простых процентов верно соотношение $S_{n}=S_{0}+I_{n}$. Пример 1 показывает, что более долгий срок хранения денег на вкладе повышает его доходность. Действительно, при увеличении или уменьшении количества периодов $n$ существования депозита сумма начисляемых процентов изменяется **линейно.** Если мы зафиксируем желание Мавры Николавны положить $10000$ рублей на вклад под $5 \%$ годовых, но будем варьировать $n$ (число лет, в течение которых деньги будут оставаться в распоряжении банка), мы сможем заметить **линейную зависимость** доходности вклада от его срока: $I_{n}=10000 *(0,01 * 5 * n)=500 n$.

Sheet Задания с выбором
A1: Название навыка | B1: Номер навыка | C1: Условия задания | D1: Номер задания | E1: Признак Т-Тренировка Д-Диагностика | F1: Ответ | G1: Верный?
A2: Определять параметры вкладов | B2: =VLOOKUP(A2,'Список навыков'!A:B,2,1) -> 17 | C2: Николай Фомич выбирает, на какой срок разместить деньги на вкладе. Он собирается восстанавливать дачу после пожара, поэтому желает получить доход в краткосрочной перспективе и минимизировать риски. Какой тип вклада он предпочтёт? | D2: 338 | E2: Т | F2: краткосрочный | G2: Да
A3: Определять параметры вкладов | B3: =VLOOKUP(A3,'Список навыков'!A:B,2,1) -> 17 | C3: Николай Фомич выбирает, на какой срок разместить деньги на вкладе. Он собирается восстанавливать дачу после пожара, поэтому желает получить доход в краткосрочной перспективе и минимизировать риски. Какой тип вклада он предпочтёт? | D3: 338 | E3: Т | F3: среднесрочный
A4: Определять параметры вкладов | B4: =VLOOKUP(A4,'Список навыков'!A:B,2,1) -> 17 | C4: Николай Фомич выбирает, на какой срок разместить деньги на вкладе. Он собирается восстанавливать дачу после пожара, поэтому желает получить доход в краткосрочной перспективе и минимизировать риски. Какой тип вклада он предпочтёт? | D4: 338 | E4: Т | F4: долгосрочный
A5: Определять параметры вкладов | B5: =VLOOKUP(A5,'Список навыков'!A:B,2,1) -> 17 | C5: Поля Верина поступает в магистратуру, обучение в которой должно занять $2$ года. Она уже оплатила два года обучения, которые должны были стоить $2$ миллиона рублей. Однако Поле повезло: она хорошо сдала экзамены и получила скидку на обучение. В следующие два года остаток от накопленных на обучение денег ей не понадобится. Предположим, изменения процентных ставок в ближайшем будущем не ожидается. Какой тип вклада стоит открыть Поле, если она хочет получить максимальный доход? | D5: 339 | E5: Т | F5: краткосрочный
A6: Определять параметры вкладов | B6: =VLOOKUP(A6,'Список навыков'!A:B,2,1) -> 17 | C6: Поля Верина поступает в магистратуру, обучение в которой должно занять $2$ года. Она уже оплатила два года обучения, которые должны были стоить $2$ миллиона рублей. Однако Поле повезло: она хорошо сдала экзамены и получила скидку на обучение. В следующие два года остаток от накопленных на обучение денег ей не понадобится. Предположим, изменения процентных ставок в ближайшем будущем не ожидается. Какой тип вклада стоит открыть Поле, если она хочет получить максимальный доход? | D6: 339 | E6: Т | F6: среднесрочный | G6: Да
A7: Определять параметры вкладов | B7: =VLOOKUP(A7,'Список навыков'!A:B,2,1) -> 17 | C7: Поля Верина поступает в магистратуру, обучение в которой должно занять $2$ года. Она уже оплатила два года обучения, которые должны были стоить $2$ миллиона рублей. Однако Поле повезло: она хорошо сдала экзамены и получила скидку на обучение. В следующие два года остаток от накопленных на обучение денег ей не понадобится. Предположим, изменения процентных ставок в ближайшем будущем не ожидается. Какой тип вклада стоит открыть Поле, если она хочет получить максимальный доход? | D7: 339 | E7: Т | F7: долгосрочный
A8: Определять параметры вкладов | B8: =VLOOKUP(A8,'Список навыков'!A:B,2,1) -> 17 | C8: Елисей только что выиграл в лотерею. Он не планирует использовать эти средства в следующие несколько лет и хочет открыть депозит по максимально выгодным условиям. Какой тип вклада ему следует открыть? | D8: 340 | E8: Т | F8: краткосрочный
